<?xml version="1.0"?>
<robot xmlns:xacro="http://www.ros.org/wiki/xacro">

  <xacro:macro name="agv" params="prefix">

    <link
    name="base_footprint_link">
    <inertial>
      <origin
        xyz="0.047411 -9.4625E-11 0.1019"
        rpy="0 0 0" />
      <mass
        value="2.8902" />
      <inertia
        ixx="0.00631"
        ixy="1.9784E-11"
        ixz="9.4573E-05"
        iyy="0.014404"
        iyz="-1.41E-11"
        izz="0.015384" />
    </inertial>
    <visual>
      <origin
        xyz="0 0 0"
        rpy="0 0 0" />
      <geometry>
        <mesh
          filename="package://agv_description/meshes/base_footprint_link.STL" />
      </geometry>
      <material
        name="">
        <color
          rgba="1 0.50196 0.50196 1" />
      </material>
    </visual>
    <collision>
      <origin
        xyz="0 0 0"
        rpy="0 0 0" />
      <geometry>
        <mesh
          filename="package://agv_description/meshes/base_footprint_link.STL" />
      </geometry>
    </collision>
  </link>
  <link
    name="base_link">
    <inertial>
      <origin
        xyz="0.047411 -9.4625E-11 0.068404"
        rpy="0 0 0" />
      <mass
        value="2.8902" />
      <inertia
        ixx="0.00631"
        ixy="1.9784E-11"
        ixz="9.4573E-05"
        iyy="0.014404"
        iyz="-1.41E-11"
        izz="0.015384" />
    </inertial>
    <visual>
      <origin
        xyz="0 0 0"
        rpy="0 0 0" />
      <geometry>
        <mesh
          filename="package://agv_description/meshes/base_link.STL" />
      </geometry>
      <material
        name="">
        <color
          rgba="1 0.50196 0.50196 1" />
      </material>
    </visual>
    <collision>
      <origin
        xyz="0 0 0"
        rpy="0 0 0" />
      <geometry>
        <mesh
          filename="package://agv_description/meshes/base_link.STL" />
      </geometry>
    </collision>
  </link>
  <joint
    name="base_joint"
    type="fixed">
    <origin
      xyz="0 0 0.0335"
      rpy="0 0 0" />
    <parent
      link="base_footprint_link" />
    <child
      link="base_link" />
    <axis
      xyz="0 0 0" />
  </joint>
  <link
    name="wheel_right_link">
    <inertial>
      <origin
        xyz="2.292E-06 0.012434 -4.2122E-06"
        rpy="0 0 0" />
      <mass
        value="0.14982" />
      <inertia
        ixx="6.1247E-05"
        ixy="2.6416E-10"
        ixz="-7.4187E-09"
        iyy="0.00010609"
        iyz="-1.117E-11"
        izz="6.1271E-05" />
    </inertial>
    <visual>
      <origin
        xyz="0 0 0"
        rpy="0 0 0" />
      <geometry>
        <mesh
          filename="package://agv_description/meshes/wheel_right_link.STL" />
      </geometry>
      <material
        name="">
        <color
          rgba="0.75294 0.75294 0.75294 1" />
      </material>
    </visual>
    <collision>
      <origin
        xyz="0 0 0"
        rpy="0 0 0" />
      <geometry>
        <mesh
          filename="package://agv_description/meshes/wheel_right_link.STL" />
      </geometry>
    </collision>
  </link>
  <joint
    name="right_wheel_joint"
    type="continuous">
    <origin
      xyz="0 -0.074554 0"
      rpy="0 0 0" />
    <parent
      link="base_link" />
    <child
      link="wheel_right_link" />
    <axis
      xyz="0 -1 0" />
  </joint>
  <link
    name="wheel_left_link">
    <inertial>
      <origin
        xyz="-2.6687E-06 -0.012434 -3.9843E-06"
        rpy="0 0 0" />
      <mass
        value="0.14982" />
      <inertia
        ixx="6.1249E-05"
        ixy="2.6407E-10"
        ixz="9.4539E-09"
        iyy="0.00010609"
        iyz="-1.3106E-11"
        izz="6.1269E-05" />
    </inertial>
    <visual>
      <origin
        xyz="0 0 0"
        rpy="0 0 0" />
      <geometry>
        <mesh
          filename="package://agv_description/meshes/wheel_left_link.STL" />
      </geometry>
      <material
        name="">
        <color
          rgba="0.75294 0.75294 0.75294 1" />
      </material>
    </visual>
    <collision>
      <origin
        xyz="0 0 0"
        rpy="0 0 0" />
      <geometry>
        <mesh
          filename="package://agv_description/meshes/wheel_left_link.STL" />
      </geometry>
    </collision>
  </link>
  <joint
    name="left_wheel_joint"
    type="continuous">
    <origin
      xyz="0 0.074554 0"
      rpy="0 0 0" />
    <parent
      link="base_link" />
    <child
      link="wheel_left_link" />
    <axis
      xyz="0 -1 0" />
  </joint>
  <link
    name="laser_link">
    <inertial>
      <origin
        xyz="0.01206 -0.00053288 -0.019315"
        rpy="0 0 0" />
      <mass
        value="0.073082" />
      <inertia
        ixx="1.958E-05"
        ixy="-1.0407E-07"
        ixz="-4.2835E-07"
        iyy="2.4126E-05"
        iyz="9.3871E-09"
        izz="4.1419E-05" />
    </inertial>
    <visual>
      <origin
        xyz="0 0 0"
        rpy="0 0 0" />
      <geometry>
        <mesh
          filename="package://agv_description/meshes/laser_link.STL" />
      </geometry>
      <material
        name="">
        <color
          rgba="0.75294 0.75294 0.75294 1" />
      </material>
    </visual>
    <collision>
      <origin
        xyz="0 0 0"
        rpy="0 0 0" />
      <geometry>
        <mesh
          filename="package://agv_description/meshes/laser_link.STL" />
      </geometry>
    </collision>
  </link>
  <joint
    name="laser_joint"
    type="fixed">
    <origin
      xyz="0.04 0 0.165549999999998"
      rpy="0 0 0" />
    <parent
      link="base_link" />
    <child
      link="laser_link" />
    <axis
      xyz="0 0 0" />
  </joint>
  <link
    name="imu_link">
    <inertial>
      <origin
        xyz="-0.0070133499706013 0.000215416646820232 -0.00333589655098029"
        rpy="0 0 0" />
      <mass
        value="0.000201021787242182" />
      <inertia
        ixx="6.13572721382298E-10"
        ixy="7.54550067895318E-14"
        ixz="1.08622666369991E-14"
        iyy="6.12931948938821E-10"
        iyz="-5.65705550087957E-14"
        izz="1.52535755073827E-10" />
    </inertial>
    <visual>
      <origin
        xyz="0 0 0"
        rpy="0 0 0" />
      <geometry>
        <mesh
          filename="package://agv_description/meshes/imu_link.STL" />
      </geometry>
      <material
        name="">
        <color
          rgba="0.752941176470588 0.752941176470588 0.752941176470588 1" />
      </material>
    </visual>
    <collision>
      <origin
        xyz="0 0 0"
        rpy="0 0 0" />
      <geometry>
        <mesh
          filename="package://agv_description/meshes/imu_link.STL" />
      </geometry>
    </collision>
  </link>
  <joint
    name="imu_joint"
    type="fixed">
    <origin
      xyz="0.161 0 0.10702"
      rpy="0 0 0" />
    <parent
      link="base_link" />
    <child
      link="imu_link" />
    <axis
      xyz="0 0 0" />
  </joint>
  <link
    name="wheel_caster_link">
    <inertial>
      <origin
        xyz="-0.00010845 -0.010695 0.0066025"
        rpy="0 0 0" />
      <mass
        value="0.0097866" />
      <inertia
        ixx="1.1699E-06"
        ixy="-9.4057E-09"
        ixz="-1.2195E-08"
        iyy="8.7802E-07"
        iyz="-9.2093E-08"
        izz="1.0252E-06" />
    </inertial>
    <visual>
      <origin
        xyz="0 0 0"
        rpy="0 0 0" />
      <geometry>
        <mesh
          filename="package://agv_description/meshes/wheel_caster_link.STL" />
      </geometry>
      <material
        name="">
        <color
          rgba="0.70588 0.70588 0.70588 1" />
      </material>
    </visual>
    <collision>
      <origin
        xyz="0 0 0"
        rpy="0 0 0" />
      <geometry>
        <mesh
          filename="package://agv_description/meshes/wheel_caster_link.STL" />
      </geometry>
    </collision>
  </link>
  <joint
    name="wheel_caster_joint"
    type="fixed">
    <origin
      xyz="0.131 0 -0.0185"
      rpy="0 0 0" />
    <parent
      link="base_link" />
    <child
      link="wheel_caster_link" />
    <axis
      xyz="0 0 0" />
  </joint>

  </xacro:macro>

</robot>
